<?xml version="1.0" ?>
<robot name="gripper">
  <link name="world"/>
  <link name="gripper_root_link">
      <visual>
          <origin xyz="0 0 1" rpy="0 0 0"/>
          <geometry>
              <box size="0.1 0.1 2.0"/>
          </geometry>
      </visual>
      <collision>
          <origin xyz="0 0 1" rpy="0 0 0"/>
          <geometry>
              <box size="0.1 0.1 2.0"/>
          </geometry>
      </collision>
      <inertial>
          <mass value="1e3" />
          <origin xyz="0.0 0.0 0.0" />
          <inertia ixx = "1000" ixy = "0.000000" ixz = "0.000000"
                    iyx = "0.000000" iyy = "1000" iyz = "0.000000"
                    izx = "0.000000" izy = "0.000000" izz = "1000" />
      </inertial>
  </link>
  <joint name="world_fixed" type="fixed">
      <origin xyz="0 0 0" rpy="0 0 0"/>
      <parent link="world"/>
      <child link="gripper_root_link"/>
  </joint>

  <joint name="base_prismatic" type="prismatic">
    <origin rpy="0 0 0" xyz="0 0 0"/>
    <parent link="gripper_root_link"/>
    <child link="base"/>
    <axis xyz="0 0 1"/>
    <limit effort="1000.0" lower="0" upper="2" velocity="10"/>
    <dynamics damping="50" friction="5"/>
  </joint>

  <link name="base">
    <visual>
      <geometry>
        <box size="1 1 0.5"/>
      </geometry>
      <origin xyz="0 0 0.25"/>
      <material name="violet">
        <color rgba="0.4 0.18 0.57 1.0" />
      </material>
    </visual>
    <collision>
      <geometry>
        <box size="1 1 0.5"/>
      </geometry>
      <origin xyz="0 0 0.25"/>
    </collision>
    <inertial>
      <mass value="50"/>
      <inertia ixx="1.0" ixy="0.0" ixz="0.0" iyy="1.0" iyz="0.0" izz="1.0"/>
    </inertial>
  </link>

  <link name="finger_right">
    <collision>
      <origin xyz="0.5 -0.05 0" rpy="0 0 0"/>
      <geometry>
        <box size="1 0.1 0.4"/>
      </geometry>
    </collision>
    <visual>
      <geometry>
        <box size="1 0.1 0.4"/>
      </geometry>
      <origin xyz="0.5 -0.05 0"/>
      <material name="grey">
        <color rgba="0.2 0.2 0.2 1"/>
      </material>
    </visual>
    <inertial>
      <mass value="5"/>
      <inertia ixx="1.0" ixy="0.0" ixz="0.0" iyy="1.0" iyz="0.0" izz="1.0"/>
    </inertial>
  </link>
  <link name="finger_left">
    <collision>
      <origin xyz="0.5 -0.05 0" rpy="0 0 0"/>
      <geometry>
        <box size="1 0.1 0.4"/>
      </geometry>
    </collision>
    <visual>
      <geometry>
        <box size="1 0.1 0.4"/>
      </geometry>
      <origin xyz="0.5 -0.05 0"/>
      <material name="grey">
        <color rgba="0.2 0.2 0.2 1"/>
      </material>
    </visual>
    <inertial>
      <mass value="5"/>
      <inertia ixx="1.0" ixy="0.0" ixz="0.0" iyy="1.0" iyz="0.0" izz="1.0"/>
    </inertial>
  </link>
  
  <joint name="right_finger_joint" type="prismatic">
    <axis xyz="0 1 0"/>
    <origin xyz="0.5 -0.48 0.25" rpy="0.0 0.0 0.0"/>
    <parent link="base"/>
    <child link="finger_right"/>
    <limit effort="1000.0" lower="0" upper="0.53" velocity="10"/>
    <!-- <dynamics damping="50" friction="5"/> -->
  </joint>
  <joint name="left_finger_joint" type="prismatic">
    <mimic joint="right_finger_joint"/>
    <axis xyz="0 1 0"/>
    <origin xyz="0.5 0.48 0.25" rpy="0.0 0.0 0"/>
    <parent link="base"/>
    <child link="finger_left"/>
    <limit effort="1000.0" lower="-0.38" upper="0" velocity="10"/>
    <!-- <dynamics damping="50" friction="5"/> -->
  </joint>
  <ros2_control name="GazeboSystem" type="system">
    <hardware>
      <plugin>gazebo_ros2_control/GazeboSystem</plugin>
    </hardware>
    <joint name="right_finger_joint">
      <command_interface name="effort"/>
      <state_interface name="position">
        <param name="initial_value">0.15</param>
      </state_interface>
      <state_interface name="velocity"/>
      <state_interface name="effort"/>
    </joint>
    <joint name="left_finger_joint">
      <param name="mimic">right_finger_joint</param>
      <param name="multiplier">-1</param>
      <command_interface name="effort"/>
      <state_interface name="position"/>
      <state_interface name="velocity"/>
      <state_interface name="effort"/>
    </joint>
    <joint name="base_prismatic">
      <command_interface name="position"/>
      <state_interface name="position">
        <param name="initial_value">0.15</param>
      </state_interface>
      <state_interface name="velocity"/>
      <state_interface name="effort"/>
    </joint>
  </ros2_control>

  <gazebo>
    <plugin filename="libgazebo_ros2_control.so" name="gazebo_ros2_control">
      <parameters>$(find gazebo_ros2_control_demos)/config/gripper_with_base_controller.yaml</parameters>
    </plugin>
  </gazebo>
</robot>
